{"aid": "iguyqpir5wx39a", "result": {"folders": ["labx", "quiz1", "lab0"], "unique_views": 20, "no_answer": 0, "change_log": [{"data": "ignxmck0fqv6ui", "anon": "no", "when": "2015-11-06T17:24:23Z", "uid": "ig2g4wrcoZE", "type": "create"}, {"uid": "iarg675erpdrg", "data": "igoluoj99uz6xp", "when": "2015-11-07T04:42:42Z", "to": "ignxmcjxagr6uh", "anon": "no", "type": "s_answer"}, {"uid": "i6q7xxh4f9y24h", "data": "igunewb2mk64cj", "when": "2015-11-11T10:13:02Z", "to": "ignxmcjxagr6uh", "anon": "no", "type": "i_answer"}], "upvote_ids": [], "id": "ignxmcjxagr6uh", "bookmarked": 5, "no_answer_followup": 0, "i_edits": [], "is_bookmarked": false, "children": [{"folders": [], "is_tag_endorse": false, "created": "2015-11-07T04:42:42Z", "config": {}, "tag_endorse_arr": [], "children": [], "bucket_name": "Today", "type": "s_answer", "tag_endorse": [], "bucket_order": 2, "data": {"embed_links": []}, "id": "igoluoj7gfd6xo", "history": [{"content": "我也是这样。", "anon": "no", "subject": "", "uid": "iarg675erpdrg", "created": "2015-11-07T04:42:42Z"}]}, {"folders": [], "is_tag_endorse": false, "created": "2015-11-11T10:13:02Z", "config": {}, "tag_endorse_arr": [], "children": [], "bucket_name": "Today", "type": "i_answer", "tag_endorse": [], "bucket_order": 2, "data": {"embed_links": []}, "id": "igunewb0iuz4ci", "history": [{"content": "<p>可能是那个时段的IBM的机器出了点问题,我现在试没问题&#xff0c;遇到创建失败&#xff0c;然后理由一大堆的的时候可以点击删除&#xff0c;然后重新创建。。。</p>", "anon": "no", "subject": "", "uid": "i6q7xxh4f9y24h", "created": "2015-11-11T10:13:02Z"}]}], "request_instructor_me": false, "nr": 540, "bucket_order": 2, "config": {}, "status": "active", "tags": ["lab0", "labx", "quiz1", "student"], "num_favorites": 0, "bucket_name": "Today", "q_edits": [], "data": {"embed_links": []}, "request_instructor": 0, "created": "2015-11-06T17:24:23Z", "is_tag_good": false, "type": "question", "s_edits": [], "my_favorite": false, "default_anonymity": "no", "t": 1447255809459, "tag_good": [], "tag_good_arr": [], "history": [{"content": "<p></p><div>\n<div>\n<div>\n<div>\n<div>\n<div>\n<div>Error: {&#34;explanation&#34;: &#34;The server has either erred or is incapable of performing the requested operation.&#34;, &#34;code&#34;: 500, &#34;error&#34;: {&#34;message&#34;: &#34;Remote error: TimeoutError QueuePool limit of size 5 overflow 10 reached, connection timed out, timeout 30\\n[u&#39;Traceback (most recent call last):\\\\n&#39;, u&#39; File \\&#34;/usr/lib/python2.6/site-packages/oslo/messaging/rpc/dispatcher.py\\&#34;, line 134, in _dispatch_and_reply\\\\n incoming.message))\\\\n&#39;, u&#39; File \\&#34;/usr/lib/python2.6/site-packages/oslo/messaging/rpc/dispatcher.py\\&#34;, line 177, in _dispatch\\\\n return self._do_dispatch(endpoint, method, ctxt, args)\\\\n&#39;, u&#39; File \\&#34;/usr/lib/python2.6/site-packages/oslo/messaging/rpc/dispatcher.py\\&#34;, line 123, in _do_dispatch\\\\n result = getattr(endpoint, method)(ctxt, **new_args)\\\\n&#39;, u&#39; File \\&#34;/usr/lib/python2.6/site-packages/heat/engine/service.py\\&#34;, line 69, in wrapped\\\\n return func(self, ctx, *args, **kwargs)\\\\n&#39;, u&#39; File \\&#34;/usr/lib/python2.6/site-packages/heat/engine/service.py\\&#34;, line 637, in create_stack\\\\n owner_id)\\\\n&#39;, u&#39; File \\&#34;/usr/lib/python2.6/site-packages/heat/engine/service.py\\&#34;, line 544, in _parse_template_and_validate_stack\\\\n self._validate_new_stack(cnxt, stack_name, tmpl)\\\\n&#39;, u&#39; File \\&#34;/usr/lib/python2.6/site-packages/heat/engine/service.py\\&#34;, line 527, in _validate_new_stack\\\\n if db_api.stack_get_by_name(cnxt, stack_name):\\\\n&#39;, u&#39; File \\&#34;/usr/lib/python2.6/site-packages/heat/db/api.py\\&#34;, line 122, in stack_get_by_name\\\\n return IMPL.stack_get_by_name(context, stack_name)\\\\n&#39;, u&#39; File \\&#34;/usr/lib/python2.6/site-packages/heat/db/sqlalchemy/api.py\\&#34;, line 281, in stack_get_by_name\\\\n return query.first()\\\\n&#39;, u&#39; File \\&#34;/usr/lib64/python2.6/site-packages/sqlalchemy/orm/query.py\\&#34;, line 2282, in first\\\\n ret = list(self[0:1])\\\\n&#39;, u&#39; File \\&#34;/usr/lib64/python2.6/site-packages/sqlalchemy/orm/query.py\\&#34;, line 2149, in __getitem__\\\\n return list(res)\\\\n&#39;, u&#39; File \\&#34;/usr/lib64/python2.6/site-packages/sqlalchemy/orm/query.py\\&#34;, line 2353, in __iter__\\\\n return self._execute_and_instances(context)\\\\n&#39;, u&#39; File \\&#34;/usr/lib64/python2.6/site-packages/sqlalchemy/orm/query.py\\&#34;, line 2366, in _execute_and_instances\\\\n close_with_result=True)\\\\n&#39;, u&#39; File \\&#34;/usr/lib64/python2.6/site-packages/sqlalchemy/orm/query.py\\&#34;, line 2357, in _connection_from_session\\\\n **kw)\\\\n&#39;, u&#39; File \\&#34;/usr/lib64/python2.6/site-packages/sqlalchemy/orm/session.py\\&#34;, line 799, in connection\\\\n close_with_result=close_with_result)\\\\n&#39;, u&#39; File \\&#34;/usr/lib64/python2.6/site-packages/sqlalchemy/orm/session.py\\&#34;, line 805, in _connection_for_bind\\\\n return engine.contextual_connect(**kwargs)\\\\n&#39;, u&#39; File \\&#34;/usr/lib64/python2.6/site-packages/sqlalchemy/engine/base.py\\&#34;, line 1661, in contextual_connect\\\\n self.pool.connect(),\\\\n&#39;, u&#39; File \\&#34;/usr/lib64/python2.6/site-packages/sqlalchemy/pool.py\\&#34;, line 272, in connect\\\\n return _ConnectionFairy(self).checkout()\\\\n&#39;, u&#39; File \\&#34;/usr/lib64/python2.6/site-packages/sqlalchemy/pool.py\\&#34;, line 431, in __init__\\\\n rec = self._connection_record = pool._do_get()\\\\n&#39;, u&#39; File \\&#34;/usr/lib64/python2.6/site-packages/sqlalchemy/pool.py\\&#34;, line 768, in _do_get\\\\n (self.size(), self.overflow(), self._timeout))\\\\n&#39;, u&#39;TimeoutError: QueuePool limit of size 5 overflow 10 reached, connection timed out, timeout 30\\\\n&#39;].&#34;, &#34;traceback&#34;: null, &#34;type&#34;: &#34;RemoteError&#34;}, &#34;title&#34;: &#34;Internal Server Error&#34;}</div>\n</div>\n</div>\n</div>\n</div>\n</div>\n</div>", "anon": "no", "subject": "create docker failed", "uid": "ig2g4wrcoZE", "created": "2015-11-06T17:24:23Z"}]}, "error": null}